Workbook

Sheet Fund 1
A1: caldt | B1: crsp_fundno | C1: mtna | D1: mret | E1: Ticker | H1: Fund Name | I1: Ticker | J1: Fund Age (Approx.) | K1: Current Fund Manager(s) | L1: Manager Tenure | M1: Manager Education | N1: Total AUM | O1: Expense Ratio | P1: Portfolio Turnover | Q1: Investment Style | R1: Investment Strategy
A2: 35825 | B2: 12663 | C2: 217.192 | D2: 0.011735 | E2: =IF(B2=12663,"FGINX",IF(B2=4516,"PGWCX","SPFIX")) -> FGINX | H2: Macquarie Growth and Income Fund | I2: FGINX | J2: 32 years | K2: Leung/Vanza | L2: N/A | M2: Not readily available | N2: $1.5 Billion | O2: 0.0077 | P2: 0.35 | Q2: Large Value | R2: Seeks long-term growth of capital and current income by investing primarily in common stocks, focusing on high-quality companies with strong and growing dividends.
A3: 35853 | B3: 12663 | C3: 233.154 | D3: 0.056338 | E3: =IF(B3=12663,"FGINX",IF(B3=4516,"PGWCX","SPFIX")) -> FGINX
A4: 35885 | B4: 12663 | C4: 250.494 | D4: 0.050196 | E4: =IF(B4=12663,"FGINX",IF(B4=4516,"PGWCX","SPFIX")) -> FGINX
A5: 35915 | B5: 12663 | C5: 261.988 | D5: 0.01868 | E5: =IF(B5=12663,"FGINX",IF(B5=4516,"PGWCX","SPFIX")) -> FGINX
A6: 35944 | B6: 12663 | C6: 260.241 | D6: -0.022744 | E6: =IF(B6=12663,"FGINX",IF(B6=4516,"PGWCX","SPFIX")) -> FGINX
A7: 35976 | B7: 12663 | C7: 274.322 | D7: 0.036787 | E7: =IF(B7=12663,"FGINX",IF(B7=4516,"PGWCX","SPFIX")) -> FGINX
A8: 36007 | B8: 12663 | C8: 272.752 | D8: -0.023196 | E8: =IF(B8=12663,"FGINX",IF(B8=4516,"PGWCX","SPFIX")) -> FGINX
A9: 36038 | B9: 12663 | C9: 240.704 | D9: -0.132789 | E9: =IF(B9=12663,"FGINX",IF(B9=4516,"PGWCX","SPFIX")) -> FGINX
A10: 36068 | B10: 12663 | C10: 257.6 | D10: 0.053037 | E10: =IF(B10=12663,"FGINX",IF(B10=4516,"PGWCX","SPFIX")) -> FGINX
A11: 36098 | B11: 12663 | C11: 277.4 | D11: 0.067774 | E11: =IF(B11=12663,"FGINX",IF(B11=4516,"PGWCX","SPFIX")) -> FGINX
A12: 36129 | B12: 12663 | C12: 295.8 | D12: 0.054995 | E12: =IF(B12=12663,"FGINX",IF(B12=4516,"PGWCX","SPFIX")) -> FGINX
A13: 36160 | B13: 12663 | C13: 317.8 | D13: 0.060144 | E13: =IF(B13=12663,"FGINX",IF(B13=4516,"PGWCX","SPFIX")) -> FGINX
A14: 36189 | B14: 12663 | C14: 335.1 | D14: 0.040928 | E14: =IF(B14=12663,"FGINX",IF(B14=4516,"PGWCX","SPFIX")) -> FGINX
... A325: 45657 | B325: 12663 | C325: 1238.3 | D325: -0.064928 | E325: =IF(B325=12663,"FGINX",IF(B325=4516,"PGWCX","SPFIX")) -> FGINX

Sheet Fund 2
A1: caldt | B1: crsp_fundno | C1: mtna | D1: mret | E1: Ticker | H1: Fund Name | I1: Ticker | J1: Fund Age (Approx.) | K1: Current Fund Manager(s) | L1: Manager Tenure | M1: Manager Education | N1: Total AUM | O1: Expense Ratio | P1: Portfolio Turnover | Q1: Investment Style | R1: Investment Strategy
A2: 35825 | B2: 4516 | C2: 1565.141 | D2: 0.021766 | E2: =IF(B2=12663,"FGINX",IF(B2=4516,"PGWCX","SPFIX")) -> PGWCX | H2: Virtus Silvant Focused Growth Fund | I2: PGWCX | J2: 41 years | K2: Sansoterra/Bhatia/Allen | L2: Since 07/25/2022 | M2: Not readily available | N2: $1.86 Billion | O2: 0.0067 | P2: 0.2 | Q2: Large Growth | R2: Seeks capital appreciation by investing in a concentrated portfolio of U.S. large-cap companies exhibiting strong business fundamentals and above-average growth potential.
A3: 35853 | B3: 4516 | C3: 1667.157 | D3: 0.075379 | E3: =IF(B3=12663,"FGINX",IF(B3=4516,"PGWCX","SPFIX")) -> PGWCX
A4: 35885 | B4: 4516 | C4: 1746.124 | D4: 0.067048 | E4: =IF(B4=12663,"FGINX",IF(B4=4516,"PGWCX","SPFIX")) -> PGWCX
A5: 35915 | B5: 4516 | C5: 1770.274 | D5: 0.018565 | E5: =IF(B5=12663,"FGINX",IF(B5=4516,"PGWCX","SPFIX")) -> PGWCX
A6: 35944 | B6: 4516 | C6: 1726.627 | D6: -0.01402 | E6: =IF(B6=12663,"FGINX",IF(B6=4516,"PGWCX","SPFIX")) -> PGWCX
A7: 35976 | B7: 4516 | C7: 1859.649 | D7: 0.078208 | E7: =IF(B7=12663,"FGINX",IF(B7=4516,"PGWCX","SPFIX")) -> PGWCX
A8: 36007 | B8: 4516 | C8: 1810.473 | D8: -0.018464 | E8: =IF(B8=12663,"FGINX",IF(B8=4516,"PGWCX","SPFIX")) -> PGWCX
A9: 36038 | B9: 4516 | C9: 1454.975 | D9: -0.181391 | E9: =IF(B9=12663,"FGINX",IF(B9=4516,"PGWCX","SPFIX")) -> PGWCX
A10: 36068 | B10: 4516 | C10: 1588.2 | D10: 0.088223 | E10: =IF(B10=12663,"FGINX",IF(B10=4516,"PGWCX","SPFIX")) -> PGWCX
A11: 36098 | B11: 4516 | C11: 1639.6 | D11: 0.03997 | E11: =IF(B11=12663,"FGINX",IF(B11=4516,"PGWCX","SPFIX")) -> PGWCX
A12: 36129 | B12: 4516 | C12: 1757.1 | D12: 0.075054 | E12: =IF(B12=12663,"FGINX",IF(B12=4516,"PGWCX","SPFIX")) -> PGWCX
A13: 36160 | B13: 4516 | C13: 1942.1 | D13: 0.119136 | E13: =IF(B13=12663,"FGINX",IF(B13=4516,"PGWCX","SPFIX")) -> PGWCX
A14: 36189 | B14: 4516 | C14: 2076.5 | D14: 0.07671 | E14: =IF(B14=12663,"FGINX",IF(B14=4516,"PGWCX","SPFIX")) -> PGWCX
... A325: 45657 | B325: 4516 | C325: 22.8 | D325: -0.013623 | E325: =IF(B325=12663,"FGINX",IF(B325=4516,"PGWCX","SPFIX")) -> PGWCX

Sheet Fund3
A1: caldt | B1: crsp_fundno | C1: mtna | D1: mret | E1: Ticker | H1: Fund Name | I1: Ticker | J1: Fund Age (Approx.) | K1: Current Fund Manager(s) | L1: Manager Tenure | M1: Manager Education | N1: Total AUM | O1: Expense Ratio | P1: Portfolio Turnover | Q1: Investment Style | R1: Investment Strategy
A2: 35825 | B2: 6981 | C2: 82.136 | D2: 0.010885 | E2: =IF(B2=12663,"FGINX",IF(B2=4516,"PGWCX","SPFIX")) -> SPFIX | H2: Shelton S&P 500 Index Fund | I2: SPFIX | J2: 33 years | K2: Steve Rogers | L2: Since 2003 | M2: U. of Iowa, UC Berkeley MBA | N2: $289.65 Million | O2: 0.005 | P2: Very Low | Q2: Large Blend | R2: Aims to replicate the total return of the S&P 500 Index. Passive, index-based strategy seeking high correlation to the benchmark.
A3: 35853 | B3: 6981 | C3: 88.86 | D3: 0.071629 | E3: =IF(B3=12663,"FGINX",IF(B3=4516,"PGWCX","SPFIX")) -> SPFIX
A4: 35885 | B4: 6981 | C4: 94.554 | D4: 0.050939 | E4: =IF(B4=12663,"FGINX",IF(B4=4516,"PGWCX","SPFIX")) -> SPFIX
A5: 35915 | B5: 6981 | C5: 97.424 | D5: 0.01043 | E5: =IF(B5=12663,"FGINX",IF(B5=4516,"PGWCX","SPFIX")) -> SPFIX
A6: 35944 | B6: 6981 | C6: 97.408 | D6: -0.017341 | E6: =IF(B6=12663,"FGINX",IF(B6=4516,"PGWCX","SPFIX")) -> SPFIX
A7: 35976 | B7: 6981 | C7: 102.932 | D7: 0.039945 | E7: =IF(B7=12663,"FGINX",IF(B7=4516,"PGWCX","SPFIX")) -> SPFIX
A8: 36007 | B8: 6981 | C8: 103.024 | D8: -0.010953 | E8: =IF(B8=12663,"FGINX",IF(B8=4516,"PGWCX","SPFIX")) -> SPFIX
A9: 36038 | B9: 6981 | C9: 88.092 | D9: -0.14274 | E9: =IF(B9=12663,"FGINX",IF(B9=4516,"PGWCX","SPFIX")) -> SPFIX
A10: 36068 | B10: 6981 | C10: 95.1 | D10: 0.063129 | E10: =IF(B10=12663,"FGINX",IF(B10=4516,"PGWCX","SPFIX")) -> SPFIX
A11: 36098 | B11: 6981 | C11: 104.3 | D11: 0.083673 | E11: =IF(B11=12663,"FGINX",IF(B11=4516,"PGWCX","SPFIX")) -> SPFIX
A12: 36129 | B12: 6981 | C12: 112.4 | D12: 0.059887 | E12: =IF(B12=12663,"FGINX",IF(B12=4516,"PGWCX","SPFIX")) -> SPFIX
A13: 36160 | B13: 6981 | C13: 125.2 | D13: 0.057832 | E13: =IF(B13=12663,"FGINX",IF(B13=4516,"PGWCX","SPFIX")) -> SPFIX
A14: 36189 | B14: 6981 | C14: 131.2 | D14: 0.043196 | E14: =IF(B14=12663,"FGINX",IF(B14=4516,"PGWCX","SPFIX")) -> SPFIX
... A325: 45657 | B325: 6981 | C325: 282.8 | D325: -0.024325 | E325: =IF(B325=12663,"FGINX",IF(B325=4516,"PGWCX","SPFIX")) -> SPFIX

Sheet Fama-French Data
A1: mktrf | B1: smb | C1: hml | D1: rf | E1: dateff | F1: umd
A2: 0.0015 | B2: -0.0101 | C2: -0.0168 | D2: 0.0043 | E2: 35825 | F2: 0.0005
A3: 0.0703 | B3: 0.0013 | C3: -0.0093 | D3: 0.0039 | E3: 35853 | F3: -0.0119
A4: 0.0476 | B4: -0.0119 | C4: 0.0138 | D4: 0.0039 | E4: 35885 | F4: 0.0213
A5: 0.0074 | B5: 0.0006 | C5: 0.0103 | D5: 0.0043 | E5: 35915 | F5: 0.0076
A6: -0.0307 | B6: -0.034 | C6: 0.0341 | D6: 0.004 | E6: 35944 | F6: 0.0191
A7: 0.0319 | B7: -0.0317 | C7: -0.0203 | D7: 0.0041 | E7: 35976 | F7: 0.0726
A8: -0.0242 | B8: -0.0483 | C8: -0.0183 | D8: 0.004 | E8: 36007 | F8: 0.0379
A9: -0.1605 | B9: -0.0547 | C9: 0.0357 | D9: 0.0043 | E9: 36038 | F9: 0.019
A10: 0.0619 | B10: -0.0002 | C10: -0.0351 | D10: 0.0046 | E10: 36068 | F10: -0.0065
A11: 0.0698 | B11: -0.0298 | C11: -0.0233 | D11: 0.0032 | E11: 36098 | F11: -0.0533
A12: 0.0607 | B12: 0.0126 | C12: -0.0324 | D12: 0.0031 | E12: 36129 | F12: 0.0113
A13: 0.0615 | B13: -0.0046 | C13: -0.0425 | D13: 0.0038 | E13: 36160 | F13: 0.0887
... A325: -0.0317 | B325: -0.0271 | C325: -0.03 | D325: 0.0037 | E325: 45657 | F325: -0.003

Sheet MF Data 
A1: Date | B1: Rp FGINX | C1: Rp PGWCX | D1: Rp SPFIX | E1: Rf | F1: Rp-Rf FGINX | G1: Rp-Rf PGWCX | H1: Rp-Rf SPFIX | I1: Rm-Rf | J1: smb | K1: hml | L1: momentum | M1: FGINX | N1: PGWCX | O1: SPFIX
A2: 35825 | B2: 0.011735 | C2: 0.021766 | D2: 0.010885 | E2: ='Fama-French Data'!D2 -> 0.0043 | F2: =B2-$E2 -> 0.007435 | G2: =C2-$E2 -> 0.017466 | H2: =D2-$E2 -> 0.006585 | I2: ='Fama-French Data'!A2 -> 0.0015 | J2: ='Fama-French Data'!B2 -> -0.0101 | K2: ='Fama-French Data'!C2 -> -0.0168 | L2: ='Fama-French Data'!F2 -> 0.0005 | M2: =(B2+1)*1000 -> 1011.735 | N2: =(C2+1)*1000 -> 1021.766 | O2: =(D2+1)*1000 -> 1010.885
A3: 35853 | B3: 0.056338 | C3: 0.075379 | D3: 0.071629 | E3: ='Fama-French Data'!D3 -> 0.0039 | F3: =B3-$E3 -> 0.052438 | G3: =C3-$E3 -> 0.071479 | H3: =D3-$E3 -> 0.067729 | I3: ='Fama-French Data'!A3 -> 0.0703 | J3: ='Fama-French Data'!B3 -> 0.0013 | K3: ='Fama-French Data'!C3 -> -0.0093 | L3: ='Fama-French Data'!F3 -> -0.0119 | M3: =M2*(B3+1) -> 1068.7341 | N3: =N2*(C3+1) -> 1098.7857 | O3: =O2*(D3+1) -> 1083.2937
A4: 35885 | B4: 0.050196 | C4: 0.067048 | D4: 0.050939 | E4: ='Fama-French Data'!D4 -> 0.0039 | F4: =B4-$E4 -> 0.046296 | G4: =C4-$E4 -> 0.063148 | H4: =D4-$E4 -> 0.047039 | I4: ='Fama-French Data'!A4 -> 0.0476 | J4: ='Fama-French Data'!B4 -> -0.0119 | K4: ='Fama-French Data'!C4 -> 0.0138 | L4: ='Fama-French Data'!F4 -> 0.0213 | M4: =M3*(B4+1) -> 1122.3803 | N4: =N3*(C4+1) -> 1172.4571 | O4: =O3*(D4+1) -> 1138.4756
A5: 35915 | B5: 0.01868 | C5: 0.018565 | D5: 0.01043 | E5: ='Fama-French Data'!D5 -> 0.0043 | F5: =B5-$E5 -> 0.01438 | G5: =C5-$E5 -> 0.014265 | H5: =D5-$E5 -> 0.00613 | I5: ='Fama-French Data'!A5 -> 0.0074 | J5: ='Fama-French Data'!B5 -> 0.0006 | K5: ='Fama-French Data'!C5 -> 0.0103 | L5: ='Fama-French Data'!F5 -> 0.0076 | M5: =M4*(B5+1) -> 1143.3464 | N5: =N4*(C5+1) -> 1194.2237 | O5: =O4*(D5+1) -> 1150.3499
A6: 35944 | B6: -0.022744 | C6: -0.01402 | D6: -0.017341 | E6: ='Fama-French Data'!D6 -> 0.004 | F6: =B6-$E6 -> -0.026744 | G6: =C6-$E6 -> -0.01802 | H6: =D6-$E6 -> -0.021341 | I6: ='Fama-French Data'!A6 -> -0.0307 | J6: ='Fama-French Data'!B6 -> -0.034 | K6: ='Fama-French Data'!C6 -> 0.0341 | L6: ='Fama-French Data'!F6 -> 0.0191 | M6: =M5*(B6+1) -> 1117.3421 | N6: =N5*(C6+1) -> 1177.4807 | O6: =O5*(D6+1) -> 1130.4017
A7: 35976 | B7: 0.036787 | C7: 0.078208 | D7: 0.039945 | E7: ='Fama-French Data'!D7 -> 0.0041 | F7: =B7-$E7 -> 0.032687 | G7: =C7-$E7 -> 0.074108 | H7: =D7-$E7 -> 0.035845 | I7: ='Fama-French Data'!A7 -> 0.0319 | J7: ='Fama-French Data'!B7 -> -0.0317 | K7: ='Fama-French Data'!C7 -> -0.0203 | L7: ='Fama-French Data'!F7 -> 0.0726 | M7: =M6*(B7+1) -> 1158.4458 | N7: =N6*(C7+1) -> 1269.5691 | O7: =O6*(D7+1) -> 1175.5556
A8: 36007 | B8: -0.023196 | C8: -0.018464 | D8: -0.010953 | E8: ='Fama-French Data'!D8 -> 0.004 | F8: =B8-$E8 -> -0.027196 | G8: =C8-$E8 -> -0.022464 | H8: =D8-$E8 -> -0.014953 | I8: ='Fama-French Data'!A8 -> -0.0242 | J8: ='Fama-French Data'!B8 -> -0.0483 | K8: ='Fama-French Data'!C8 -> -0.0183 | L8: ='Fama-French Data'!F8 -> 0.0379 | M8: =M7*(B8+1) -> 1131.5745 | N8: =N7*(C8+1) -> 1246.1278 | O8: =O7*(D8+1) -> 1162.6797
A9: 36038 | B9: -0.132789 | C9: -0.181391 | D9: -0.14274 | E9: ='Fama-French Data'!D9 -> 0.0043 | F9: =B9-$E9 -> -0.137089 | G9: =C9-$E9 -> -0.185691 | H9: =D9-$E9 -> -0.14704 | I9: ='Fama-French Data'!A9 -> -0.1605 | J9: ='Fama-French Data'!B9 -> -0.0547 | K9: ='Fama-French Data'!C9 -> 0.0357 | L9: ='Fama-French Data'!F9 -> 0.019 | M9: =M8*(B9+1) -> 981.31381 | N9: =N8*(C9+1) -> 1020.0914 | O9: =O8*(D9+1) -> 996.7188
A10: 36068 | B10: 0.053037 | C10: 0.088223 | D10: 0.063129 | E10: ='Fama-French Data'!D10 -> 0.0046 | F10: =B10-$E10 -> 0.048437 | G10: =C10-$E10 -> 0.083623 | H10: =D10-$E10 -> 0.058529 | I10: ='Fama-French Data'!A10 -> 0.0619 | J10: ='Fama-French Data'!B10 -> -0.0002 | K10: ='Fama-French Data'!C10 -> -0.0351 | L10: ='Fama-French Data'!F10 -> -0.0065 | M10: =M9*(B10+1) -> 1033.3598 | N10: =N9*(C10+1) -> 1110.087 | O10: =O9*(D10+1) -> 1059.6407
A11: 36098 | B11: 0.067774 | C11: 0.03997 | D11: 0.083673 | E11: ='Fama-French Data'!D11 -> 0.0032 | F11: =B11-$E11 -> 0.064574 | G11: =C11-$E11 -> 0.03677 | H11: =D11-$E11 -> 0.080473 | I11: ='Fama-French Data'!A11 -> 0.0698 | J11: ='Fama-French Data'!B11 -> -0.0298 | K11: ='Fama-French Data'!C11 -> -0.0233 | L11: ='Fama-French Data'!F11 -> -0.0533 | M11: =M10*(B11+1) -> 1103.3947 | N11: =N10*(C11+1) -> 1154.4572 | O11: =O10*(D11+1) -> 1148.304
A12: 36129 | B12: 0.054995 | C12: 0.075054 | D12: 0.059887 | E12: ='Fama-French Data'!D12 -> 0.0031 | F12: =B12-$E12 -> 0.051895 | G12: =C12-$E12 -> 0.071954 | H12: =D12-$E12 -> 0.056787 | I12: ='Fama-French Data'!A12 -> 0.0607 | J12: ='Fama-French Data'!B12 -> 0.0126 | K12: ='Fama-French Data'!C12 -> -0.0324 | L12: ='Fama-French Data'!F12 -> 0.0113 | M12: =M11*(B12+1) -> 1164.0759 | N12: =N11*(C12+1) -> 1241.1038 | O12: =O11*(D12+1) -> 1217.0724
A13: 36160 | B13: 0.060144 | C13: 0.119136 | D13: 0.057832 | E13: ='Fama-French Data'!D13 -> 0.0038 | F13: =B13-$E13 -> 0.056344 | G13: =C13-$E13 -> 0.115336 | H13: =D13-$E13 -> 0.054032 | I13: ='Fama-French Data'!A13 -> 0.0615 | J13: ='Fama-French Data'!B13 -> -0.0046 | K13: ='Fama-French Data'!C13 -> -0.0425 | L13: ='Fama-French Data'!F13 -> 0.0887 | M13: =M12*(B13+1) -> 1234.088 | N13: =N12*(C13+1) -> 1388.9639 | O13: =O12*(D13+1) -> 1287.4582
A14: 36189 | B14: 0.040928 | C14: 0.07671 | D14: 0.043196 | E14: ='Fama-French Data'!D14 -> 0.0035 | F14: =B14-$E14 -> 0.037428 | G14: =C14-$E14 -> 0.07321 | H14: =D14-$E14 -> 0.039696 | I14: ='Fama-French Data'!A14 -> 0.0348 | J14: ='Fama-French Data'!B14 -> 0.0067 | K14: ='Fama-French Data'!C14 -> -0.0446 | L14: ='Fama-French Data'!F14 -> 0.0284 | M14: =M13*(B14+1) -> 1284.5968 | N14: =N13*(C14+1) -> 1495.5113 | O14: =O13*(D14+1) -> 1343.0712
... A325: 45657 | B325: -0.064928 | C325: -0.013623 | D325: -0.024325 | E325: ='Fama-French Data'!D325 -> 0.0037 | F325: =B325-$E325 -> -0.068628 | G325: =C325-$E325 -> -0.017323 | H325: =D325-$E325 -> -0.028025 | I325: ='Fama-French Data'!A325 -> -0.0317 | J325: ='Fama-French Data'!B325 -> -0.0271 | K325: ='Fama-French Data'!C325 -> -0.03 | L325: ='Fama-French Data'!F325 -> -0.003 | M325: =M324*(B325+1) -> 6367.6486 | N325: =N324*(C325+1) -> 10527.134 | O325: =O324*(D325+1) -> 9350.6305

Sheet Alphas+Ratios
A1: Fund | B1: Period | C1: Alpha (1-Factor) | D1: Alpha (3-Factor) | E1: Alpha (4-Factor) | F1: Sharpe Ratio | G1: Treynor Ratio | I1: Fund | J1: Alpha (1-Factor) | K1: Alpha (3-Factor) | L1: Alpha (4-Factor)
A2: FGINX | B2: 1998-2013 | C2: ='Alphas 1998-2013'!B20*12 -> -0.0013491384 | D2: ='Alphas 1998-2013'!L20*12 -> -0.0058035133 | E2: ='Alphas 1998-2013'!V20*12 -> -0.0090707639 | F2: ='Sharpe+Treynor Ratio'!F3 -> 0.314216 | G2: ='Sharpe+Treynor Ratio'!F15 -> 0.053517176 | I2: =_xlfn.CONCAT(A2," ",B2) -> FGINX 1998-2013 | J2: =C2 -> -0.0013491384 | K2: =D2 -> -0.0058035133 | L2: =E2 -> -0.0090707639
A3: PGWCX | B3: 1998-2013 | C3: ='Alphas 1998-2013'!B43*12 -> -0.012038552 | D3: ='Alphas 1998-2013'!L43*12 -> -0.00072693556 | E3: ='Alphas 1998-2013'!V43*12 -> -0.013469138 | F3: ='Sharpe+Treynor Ratio'!F4 -> 0.24533049 | G3: ='Sharpe+Treynor Ratio'!F16 -> 0.043764701 | I3: =_xlfn.CONCAT(A3," ",B3) -> PGWCX 1998-2013 | J3: =C3 -> -0.012038552 | K3: =D3 -> -0.00072693556 | L3: =E3 -> -0.013469138
A4: SPFIX | B4: 1998-2013 | C4: ='Alphas 1998-2013'!B66*12 -> -0.0040047661 | D4: ='Alphas 1998-2013'!L66*12 -> -0.0011466091 | E4: ='Alphas 1998-2013'!V66*12 -> 0.00052008425 | F4: ='Sharpe+Treynor Ratio'!F5 -> 0.30221088 | G4: ='Sharpe+Treynor Ratio'!F17 -> 0.050693217 | I4: =_xlfn.CONCAT(A4," ",B4) -> SPFIX 1998-2013 | J4: =C4 -> -0.0040047661 | K4: =D4 -> -0.0011466091 | L4: =E4 -> 0.00052008425
A5: FGINX | B5: 1998-2006 | C5: ='Alphas 1998-2006 '!B20*12 -> -0.00087326499 | D5: ='Alphas 1998-2006 '!L20*12 -> -0.012877555 | E5: ='Alphas 1998-2006 '!V20*12 -> -0.021061671 | F5: ='Sharpe+Treynor Ratio'!F6 -> 0.23848867 | G5: ='Sharpe+Treynor Ratio'!F18 -> 0.039819913 | I5: =_xlfn.CONCAT(A5," ",B5) -> FGINX 1998-2006 | J5: =C5 -> -0.00087326499 | K5: =D5 -> -0.012877555 | L5: =E5 -> -0.021061671
A6: PGWCX | B6: 1998-2006 | C6: ='Alphas 1998-2006 '!B44*12 -> -0.03000721 | D6: ='Alphas 1998-2006 '!L44*12 -> -0.0047059124 | E6: ='Alphas 1998-2006 '!V44*12 -> -0.033785495 | F6: ='Sharpe+Treynor Ratio'!F7 -> 0.089307571 | G6: ='Sharpe+Treynor Ratio'!F19 -> 0.015485335 | I6: =_xlfn.CONCAT(A6," ",B6) -> PGWCX 1998-2006 | J6: =C6 -> -0.03000721 | K6: =D6 -> -0.0047059124 | L6: =E6 -> -0.033785495
A7: SPFIX | B7: 1998-2006 | C7: ='Alphas 1998-2006 '!B68*12 -> -0.0020355385 | D7: ='Alphas 1998-2006 '!L68*12 -> 0.00029235219 | E7: ='Alphas 1998-2006 '!V68*12 -> 0.0045712071 | F7: ='Sharpe+Treynor Ratio'!F8 -> 0.23599767 | G7: ='Sharpe+Treynor Ratio'!F20 -> 0.038608599 | I7: =_xlfn.CONCAT(A7," ",B7) -> SPFIX 1998-2006 | J7: =C7 -> -0.0020355385 | K7: =D7 -> 0.00029235219 | L7: =E7 -> 0.0045712071
A8: FGINX | B8: 2007-2013 | C8: ='Alphas 2007-2013'!B20*12 -> -0.0039563503 | D8: ='Alphas 2007-2013'!L20*12 -> -0.0066587541 | E8: ='Alphas 2007-2013'!V20*12 -> -0.0067124527 | F8: ='Sharpe+Treynor Ratio'!F9 -> 0.39532169 | G8: ='Sharpe+Treynor Ratio'!F21 -> 0.069258842 | I8: =_xlfn.CONCAT(A8," ",B8) -> FGINX 2007-2013 | J8: =C8 -> -0.0039563503 | K8: =D8 -> -0.0066587541 | L8: =E8 -> -0.0067124527
A9: PGWCX | B9: 2007-2013 | C9: ='Alphas 2007-2013'!B44*12 -> 0.014126599 | D9: ='Alphas 2007-2013'!L44*12 -> -0.0015032619 | E9: ='Alphas 2007-2013'!V44*12 -> -0.001426314 | F9: ='Sharpe+Treynor Ratio'!F10 -> 0.48246294 | G9: ='Sharpe+Treynor Ratio'!F22 -> 0.087807971 | I9: =_xlfn.CONCAT(A9," ",B9) -> PGWCX 2007-2013 | J9: =C9 -> 0.014126599 | K9: =D9 -> -0.0015032619 | L9: =E9 -> -0.001426314
A10: SPFIX | B10: 2007-2013 | C10: ='Alphas 2007-2013'!B68*12 -> -0.0071194599 | D10: ='Alphas 2007-2013'!L68*12 -> -0.004462724 | E10: ='Alphas 2007-2013'!V68*12 -> -0.0044595081 | F10: ='Sharpe+Treynor Ratio'!F11 -> 0.37808781 | G10: ='Sharpe+Treynor Ratio'!F23 -> 0.065729718 | I10: =_xlfn.CONCAT(A10," ",B10) -> SPFIX 2007-2013 | J10: =C10 -> -0.0071194599 | K10: =D10 -> -0.004462724 | L10: =E10 -> -0.0044595081

Sheet Stock Data
A1: Ticker | B1: BM | C1: PRC | D1: SHROUT | E1: Size | F1: Size Decile | G1: Size | H1: BM Decile
A2: AAPL | B2: 0.016 | C2: 250.42 | D2: 15115823 | E2: =C2*D2 -> 3.7853044e+09 | F2: =MATCH(E2/1000000, {10.3,18.7,27.5,40.1,55.8,80.6,120.4,200.9,350.2,1029.9}, 1) -> 10 | G2: =IF(F2>6,"Big","Small") -> Big | H2: =MATCH(B2, {0,0.064,0.11,0.142,0.183,0.218,0.258,0.292,0.349,0.398,0.461,0.508,0.56,0.622,0.684,0.756,0.822,0.927,1.11,1.413,6.553}, 1) -> 1 | I2: =IF(H2<10,"Growth","Value") -> Growth | J2: =G2&" "&I2 -> Big Growth
A3: LLY | B3: 0.018 | C3: 772 | D3: 949316 | E3: =C3*D3 -> 732871952 | F3: =MATCH(E3/1000000, {10.3,18.7,27.5,40.1,55.8,80.6,120.4,200.9,350.2,1029.9}, 1) -> 9 | G3: =IF(F3>6,"Big","Small") -> Big | H3: =MATCH(B3, {0,0.064,0.11,0.142,0.183,0.218,0.258,0.292,0.349,0.398,0.461,0.508,0.56,0.622,0.684,0.756,0.822,0.927,1.11,1.413,6.553}, 1) -> 1 | I3: =IF(H3<10,"Growth","Value") -> Growth | J3: =G3&" "&I3 -> Big Growth
A4: NVDA | B4: 0.02 | C4: 134.28999 | D4: 24490000 | E4: =C4*D4 -> 3.2887619e+09 | F4: =MATCH(E4/1000000, {10.3,18.7,27.5,40.1,55.8,80.6,120.4,200.9,350.2,1029.9}, 1) -> 10 | G4: =IF(F4>6,"Big","Small") -> Big | H4: =MATCH(B4, {0,0.064,0.11,0.142,0.183,0.218,0.258,0.292,0.349,0.398,0.461,0.508,0.56,0.622,0.684,0.756,0.822,0.927,1.11,1.413,6.553}, 1) -> 1 | I4: =IF(H4<10,"Growth","Value") -> Growth | J4: =G4&" "&I4 -> Big Growth
A5: BKNG | B5: 0.045 | C5: 4968.4199 | D5: 33097 | E5: =C5*D5 -> 1.6443979e+08 | F5: =MATCH(E5/1000000, {10.3,18.7,27.5,40.1,55.8,80.6,120.4,200.9,350.2,1029.9}, 1) -> 7 | G5: =IF(F5>6,"Big","Small") -> Big | H5: =MATCH(B5, {0,0.064,0.11,0.142,0.183,0.218,0.258,0.292,0.349,0.398,0.461,0.508,0.56,0.622,0.684,0.756,0.822,0.927,1.11,1.413,6.553}, 1) -> 1 | I5: =IF(H5<10,"Growth","Value") -> Growth | J5: =G5&" "&I5 -> Big Growth
A6: TJX | B6: 0.066 | C6: 120.81 | D6: 1124158 | E6: =C6*D6 -> 1.3580953e+08 | F6: =MATCH(E6/1000000, {10.3,18.7,27.5,40.1,55.8,80.6,120.4,200.9,350.2,1029.9}, 1) -> 7 | G6: =IF(F6>6,"Big","Small") -> Big | H6: =MATCH(B6, {0,0.064,0.11,0.142,0.183,0.218,0.258,0.292,0.349,0.398,0.461,0.508,0.56,0.622,0.684,0.756,0.822,0.927,1.11,1.413,6.553}, 1) -> 2 | I6: =IF(H6<10,"Growth","Value") -> Growth | J6: =G6&" "&I6 -> Big Growth
A7: NFLX | B7: 0.075 | C7: 891.32001 | D7: 427458 | E7: =C7*D7 -> 3.8100187e+08 | F7: =MATCH(E7/1000000, {10.3,18.7,27.5,40.1,55.8,80.6,120.4,200.9,350.2,1029.9}, 1) -> 9 | G7: =IF(F7>6,"Big","Small") -> Big | H7: =MATCH(B7, {0,0.064,0.11,0.142,0.183,0.218,0.258,0.292,0.349,0.398,0.461,0.508,0.56,0.622,0.684,0.756,0.822,0.927,1.11,1.413,6.553}, 1) -> 2 | I7: =IF(H7<10,"Growth","Value") -> Growth | J7: =G7&" "&I7 -> Big Growth
A8: V | B8: 0.08 | C8: 316.04001 | D8: 1729399 | E8: =C8*D8 -> 5.4655928e+08 | F8: =MATCH(E8/1000000, {10.3,18.7,27.5,40.1,55.8,80.6,120.4,200.9,350.2,1029.9}, 1) -> 9 | G8: =IF(F8>6,"Big","Small") -> Big | H8: =MATCH(B8, {0,0.064,0.11,0.142,0.183,0.218,0.258,0.292,0.349,0.398,0.461,0.508,0.56,0.622,0.684,0.756,0.822,0.927,1.11,1.413,6.553}, 1) -> 2 | I8: =IF(H8<10,"Growth","Value") -> Growth | J8: =G8&" "&I8 -> Big Growth
A9: TSLA | B9: 0.083 | C9: 403.84 | D9: 3210060 | E9: =C9*D9 -> 1.2963506e+09 | F9: =MATCH(E9/1000000, {10.3,18.7,27.5,40.1,55.8,80.6,120.4,200.9,350.2,1029.9}, 1) -> 10 | G9: =IF(F9>6,"Big","Small") -> Big | H9: =MATCH(B9, {0,0.064,0.11,0.142,0.183,0.218,0.258,0.292,0.349,0.398,0.461,0.508,0.56,0.622,0.684,0.756,0.822,0.927,1.11,1.413,6.553}, 1) -> 2 | I9: =IF(H9<10,"Growth","Value") -> Growth | J9: =G9&" "&I9 -> Big Growth
A10: AVGO | B10: 0.091 | C10: 231.84 | D10: 4686000 | E10: =C10*D10 -> 1086402240 | F10: =MATCH(E10/1000000, {10.3,18.7,27.5,40.1,55.8,80.6,120.4,200.9,350.2,1029.9}, 1) -> 10 | G10: =IF(F10>6,"Big","Small") -> Big | H10: =MATCH(B10, {0,0.064,0.11,0.142,0.183,0.218,0.258,0.292,0.349,0.398,0.461,0.508,0.56,0.622,0.684,0.756,0.822,0.927,1.11,1.413,6.553}, 1) -> 2 | I10: =IF(H10<10,"Growth","Value") -> Growth | J10: =G10&" "&I10 -> Big Growth
A11: MSFT | B11: 0.091 | C11: 421.5 | D11: 7434881 | E11: =C11*D11 -> 3.1338023e+09 | F11: =MATCH(E11/1000000, {10.3,18.7,27.5,40.1,55.8,80.6,120.4,200.9,350.2,1029.9}, 1) -> 10 | G11: =IF(F11>6,"Big","Small") -> Big | H11: =MATCH(B11, {0,0.064,0.11,0.142,0.183,0.218,0.258,0.292,0.349,0.398,0.461,0.508,0.56,0.622,0.684,0.756,0.822,0.927,1.11,1.413,6.553}, 1) -> 2 | I11: =IF(H11<10,"Growth","Value") -> Growth | J11: =G11&" "&I11 -> Big Growth
A12: GE | B12: 0.092 | C12: 166.78999 | D12: 1082294 | E12: =C12*D12 -> 1.8051581e+08 | F12: =MATCH(E12/1000000, {10.3,18.7,27.5,40.1,55.8,80.6,120.4,200.9,350.2,1029.9}, 1) -> 7 | G12: =IF(F12>6,"Big","Small") -> Big | H12: =MATCH(B12, {0,0.064,0.11,0.142,0.183,0.218,0.258,0.292,0.349,0.398,0.461,0.508,0.56,0.622,0.684,0.756,0.822,0.927,1.11,1.413,6.553}, 1) -> 2 | I12: =IF(H12<10,"Growth","Value") -> Growth | J12: =G12&" "&I12 -> Big Growth
A13: META | B13: 0.114 | C13: 585.51001 | D13: 2180001 | E13: =C13*D13 -> 1.2764124e+09 | F13: =MATCH(E13/1000000, {10.3,18.7,27.5,40.1,55.8,80.6,120.4,200.9,350.2,1029.9}, 1) -> 10 | G13: =IF(F13>6,"Big","Small") -> Big | H13: =MATCH(B13, {0,0.064,0.11,0.142,0.183,0.218,0.258,0.292,0.349,0.398,0.461,0.508,0.56,0.622,0.684,0.756,0.822,0.927,1.11,1.413,6.553}, 1) -> 3 | I13: =IF(H13<10,"Growth","Value") -> Growth | J13: =G13&" "&I13 -> Big Growth
... A33: RCL | B33: 0.14 | C33: 230.69 | D33: 268875 | E33: =C33*D33 -> 62026774 | F33: =MATCH(E33/1000000, {10.3,18.7,27.5,40.1,55.8,80.6,120.4,200.9,350.2,1029.9}, 1) -> 5 | G33: =IF(F33>6,"Big","Small") -> Small | H33: =MATCH(B33, {0,0.064,0.11,0.142,0.183,0.218,0.258,0.292,0.349,0.398,0.461,0.508,0.56,0.622,0.684,0.756,0.822,0.927,1.11,1.413,6.553}, 1) -> 3 | I33: =IF(H33<10,"Growth","Value") -> Growth | J33: =G33&" "&I33 -> Small Growth

Sheet MF Stocks
A1: FGINX | I1: FGINX Size by Style | J1: Total Size
A2: security_name | B2: Ticker | C2: =VLOOKUP(B2,'Stock Data'!$A$1:$E$33,2,FALSE) -> BM | D2: =VLOOKUP($B2,'Stock Data'!$A$1:$E$33,3,FALSE) -> PRC | E2: =VLOOKUP($B2,'Stock Data'!$A$1:$E$33,4,FALSE) -> SHROUT | F2: =VLOOKUP($B2,'Stock Data'!$A$1:$E$33,5,FALSE) -> Size | I2: Big Growth | J2: =SUMIFS($F$3:$F$17,$G$3:$G$17,"Big Growth") -> 1.9995652e+09
A3: CISCO SYSTEMS INC | B3: CSCO | C3: =VLOOKUP(B3,'Stock Data'!$A$1:$E$33,2,FALSE) -> 0.208 | D3: =VLOOKUP($B3,'Stock Data'!$A$1:$E$33,3,FALSE) -> 59.2 | E3: =VLOOKUP($B3,'Stock Data'!$A$1:$E$33,4,FALSE) -> 3982758 | F3: =VLOOKUP($B3,'Stock Data'!$A$1:$E$33,5,FALSE) -> 2.3577927e+08 | G3: =VLOOKUP($B3,'Stock Data'!$A$1:$J$33,10,FALSE) -> Big Growth | I3: Big Value | J3: =SUMIFS($F$3:$F$17,$G$3:$G$17,"Big Value") -> 1.0081129e+09
A4: EXXON MOBIL CORP | B4: XOM | C4: =VLOOKUP(B4,'Stock Data'!$A$1:$E$33,2,FALSE) -> 0.6 | D4: =VLOOKUP($B4,'Stock Data'!$A$1:$E$33,3,FALSE) -> 107.57 | E4: =VLOOKUP($B4,'Stock Data'!$A$1:$E$33,4,FALSE) -> 4395095 | F4: =VLOOKUP($B4,'Stock Data'!$A$1:$E$33,5,FALSE) -> 4.7278037e+08 | G4: =VLOOKUP($B4,'Stock Data'!$A$1:$J$33,10,FALSE) -> Big Value | I4: Small Growth | J4: =SUMIFS($F$3:$F$17,$G$3:$G$17,"Small Growth") -> 3.0217565e+08
A5: PHILIP MORRIS INTERNATIONAL INC | B5: PM | C5: =VLOOKUP(B5,'Stock Data'!$A$1:$E$33,2,FALSE) -> 0.016 | D5: =VLOOKUP($B5,'Stock Data'!$A$1:$E$33,3,FALSE) -> 120.35 | E5: =VLOOKUP($B5,'Stock Data'!$A$1:$E$33,4,FALSE) -> 1554833 | F5: =VLOOKUP($B5,'Stock Data'!$A$1:$E$33,5,FALSE) -> 1.8712415e+08 | G5: =VLOOKUP($B5,'Stock Data'!$A$1:$J$33,10,FALSE) -> Big Growth | I5: Small Value | J5: =SUMIFS($F$3:$F$17,$G$3:$G$17,"Small Value") -> 2.0981871e+08
A6: CITIGROUP INC | B6: C | C6: =VLOOKUP(B6,'Stock Data'!$A$1:$E$33,2,FALSE) -> 1.628 | D6: =VLOOKUP($B6,'Stock Data'!$A$1:$E$33,3,FALSE) -> 70.39 | E6: =VLOOKUP($B6,'Stock Data'!$A$1:$E$33,4,FALSE) -> 1891265 | F6: =VLOOKUP($B6,'Stock Data'!$A$1:$E$33,5,FALSE) -> 1.3312614e+08 | G6: =VLOOKUP($B6,'Stock Data'!$A$1:$J$33,10,FALSE) -> Big Value
A7: GILEAD SCIENCES INC | B7: GILD | C7: =VLOOKUP(B7,'Stock Data'!$A$1:$E$33,2,FALSE) -> 0.184 | D7: =VLOOKUP($B7,'Stock Data'!$A$1:$E$33,3,FALSE) -> 92.37 | E7: =VLOOKUP($B7,'Stock Data'!$A$1:$E$33,4,FALSE) -> 1246266 | F7: =VLOOKUP($B7,'Stock Data'!$A$1:$E$33,5,FALSE) -> 1.1511759e+08 | G7: =VLOOKUP($B7,'Stock Data'!$A$1:$J$33,10,FALSE) -> Small Growth
A8: C V S HEALTH CORP | B8: CVS | C8: =VLOOKUP(B8,'Stock Data'!$A$1:$E$33,2,FALSE) -> 0.993 | D8: =VLOOKUP($B8,'Stock Data'!$A$1:$E$33,3,FALSE) -> 44.89 | E8: =VLOOKUP($B8,'Stock Data'!$A$1:$E$33,4,FALSE) -> 1258408 | F8: =VLOOKUP($B8,'Stock Data'!$A$1:$E$33,5,FALSE) -> 56489935 | G8: =VLOOKUP($B8,'Stock Data'!$A$1:$J$33,10,FALSE) -> Small Value | I8: PGWCX Size by Style | J8: Total Size
A9: CIGNA GROUP | B9: CI | C9: =VLOOKUP(B9,'Stock Data'!$A$1:$E$33,2,FALSE) -> 0.504 | D9: =VLOOKUP($B9,'Stock Data'!$A$1:$E$33,3,FALSE) -> 276.14001 | E9: =VLOOKUP($B9,'Stock Data'!$A$1:$E$33,4,FALSE) -> 278153 | F9: =VLOOKUP($B9,'Stock Data'!$A$1:$E$33,5,FALSE) -> 76809172 | G9: =VLOOKUP($B9,'Stock Data'!$A$1:$J$33,10,FALSE) -> Small Value | I9: Big Growth | J9: =SUMIFS($F$22:$F$36,$G$22:$G$36,"Big Growth") -> 1.8010512e+10
A10: MCKESSON H B O C INC | B10: MCK | C10: =VLOOKUP(B10,'Stock Data'!$A$1:$E$33,2,FALSE) -> 0.335 | D10: =VLOOKUP($B10,'Stock Data'!$A$1:$E$33,3,FALSE) -> 569.90997 | E10: =VLOOKUP($B10,'Stock Data'!$A$1:$E$33,4,FALSE) -> 126940 | F10: =VLOOKUP($B10,'Stock Data'!$A$1:$E$33,5,FALSE) -> 72344372 | G10: =VLOOKUP($B10,'Stock Data'!$A$1:$J$33,10,FALSE) -> Small Growth | I10: Big Value | J10: =SUMIFS($F$22:$F$36,$G$22:$G$36,"Big Value") -> 0
A11: BOOKING HOLDINGS INC | B11: BKNG | C11: =VLOOKUP(B11,'Stock Data'!$A$1:$E$33,2,FALSE) -> 0.045 | D11: =VLOOKUP($B11,'Stock Data'!$A$1:$E$33,3,FALSE) -> 4968.4199 | E11: =VLOOKUP($B11,'Stock Data'!$A$1:$E$33,4,FALSE) -> 33097 | F11: =VLOOKUP($B11,'Stock Data'!$A$1:$E$33,5,FALSE) -> 1.6443979e+08 | G11: =VLOOKUP($B11,'Stock Data'!$A$1:$J$33,10,FALSE) -> Big Growth | I11: Small Growth | J11: =SUMIFS($F$22:$F$36,$G$22:$G$36,"Small Growth") -> 2.0117248e+08
A12: META PLATFORMS INC | B12: META | C12: =VLOOKUP(B12,'Stock Data'!$A$1:$E$33,2,FALSE) -> 0.114 | D12: =VLOOKUP($B12,'Stock Data'!$A$1:$E$33,3,FALSE) -> 585.51001 | E12: =VLOOKUP($B12,'Stock Data'!$A$1:$E$33,4,FALSE) -> 2180001 | F12: =VLOOKUP($B12,'Stock Data'!$A$1:$E$33,5,FALSE) -> 1.2764124e+09 | G12: =VLOOKUP($B12,'Stock Data'!$A$1:$J$33,10,FALSE) -> Big Growth | I12: Small Value | J12: =SUMIFS($F$22:$F$36,$G$22:$G$36,"Small Value") -> 0
A13: BRISTOL MYERS SQUIBB CO | B13: BMY | C13: =VLOOKUP(B13,'Stock Data'!$A$1:$E$33,2,FALSE) -> 0.167 | D13: =VLOOKUP($B13,'Stock Data'!$A$1:$E$33,3,FALSE) -> 56.56 | E13: =VLOOKUP($B13,'Stock Data'!$A$1:$E$33,4,FALSE) -> 2028177 | F13: =VLOOKUP($B13,'Stock Data'!$A$1:$E$33,5,FALSE) -> 1.1471369e+08 | G13: =VLOOKUP($B13,'Stock Data'!$A$1:$J$33,10,FALSE) -> Small Growth
A14: WELLS FARGO & CO NEW | B14: WFC | C14: =VLOOKUP(B14,'Stock Data'!$A$1:$E$33,2,FALSE) -> 0.871 | D14: =VLOOKUP($B14,'Stock Data'!$A$1:$E$33,3,FALSE) -> 70.24 | E14: =VLOOKUP($B14,'Stock Data'!$A$1:$E$33,4,FALSE) -> 3329491 | F14: =VLOOKUP($B14,'Stock Data'!$A$1:$E$33,5,FALSE) -> 2.3386345e+08 | G14: =VLOOKUP($B14,'Stock Data'!$A$1:$J$33,10,FALSE) -> Big Value
A15: P N C FINANCIAL SERVICES GRP INC | B15: PNC | C15: =VLOOKUP(B15,'Stock Data'!$A$1:$E$33,2,FALSE) -> 0.674 | D15: =VLOOKUP($B15,'Stock Data'!$A$1:$E$33,3,FALSE) -> 192.85001 | E15: =VLOOKUP($B15,'Stock Data'!$A$1:$E$33,4,FALSE) -> 396783 | F15: =VLOOKUP($B15,'Stock Data'!$A$1:$E$33,5,FALSE) -> 76519606 | G15: =VLOOKUP($B15,'Stock Data'!$A$1:$J$33,10,FALSE) -> Small Value | I15: SPFIX Size by Style | J15: Total Size
A16: T J X COMPANIES INC NEW | B16: TJX | C16: =VLOOKUP(B16,'Stock Data'!$A$1:$E$33,2,FALSE) -> 0.066 | D16: =VLOOKUP($B16,'Stock Data'!$A$1:$E$33,3,FALSE) -> 120.81 | E16: =VLOOKUP($B16,'Stock Data'!$A$1:$E$33,4,FALSE) -> 1124158 | F16: =VLOOKUP($B16,'Stock Data'!$A$1:$E$33,5,FALSE) -> 1.3580953e+08 | G16: =VLOOKUP($B16,'Stock Data'!$A$1:$J$33,10,FALSE) -> Big Growth | I16: Big Growth | J16: =SUMIFS($F$41:$F$55,$G$41:$G$55,"Big Growth") -> 2.0046515e+10
A17: VERIZON COMMUNICATIONS INC | B17: VZ | C17: =VLOOKUP(B17,'Stock Data'!$A$1:$E$33,2,FALSE) -> 0.752 | D17: =VLOOKUP($B17,'Stock Data'!$A$1:$E$33,3,FALSE) -> 39.99 | E17: =VLOOKUP($B17,'Stock Data'!$A$1:$E$33,4,FALSE) -> 4209626 | F17: =VLOOKUP($B17,'Stock Data'!$A$1:$E$33,5,FALSE) -> 1.6834294e+08 | G17: =VLOOKUP($B17,'Stock Data'!$A$1:$J$33,10,FALSE) -> Big Value | I17: Big Value | J17: =SUMIFS($F$41:$F$55,$G$41:$G$55,"Big Value") -> 2.2461135e+09
I18: Small Growth | J18: =SUMIFS($F$41:$F$55,$G$41:$G$55,"Small Growth") -> 0
I19: Small Value | J19: =SUMIFS($F$41:$F$55,$G$41:$G$55,"Small Value") -> 0
A20: PGWCX
A21: security_name | B21: Ticker | C21: =VLOOKUP(B21,'Stock Data'!$A$1:$E$33,2,FALSE) -> BM | D21: =VLOOKUP($B21,'Stock Data'!$A$1:$E$33,3,FALSE) -> PRC | E21: =VLOOKUP($B21,'Stock Data'!$A$1:$E$33,4,FALSE) -> SHROUT | F21: =VLOOKUP($B21,'Stock Data'!$A$1:$E$33,5,FALSE) -> Size
A22: NVIDIA CORP | B22: NVDA | C22: =VLOOKUP($B22,'Stock Data'!$A$1:$E$33,2,FALSE) -> 0.02 | D22: =VLOOKUP($B22,'Stock Data'!$A$1:$E$33,3,FALSE) -> 134.28999 | E22: =VLOOKUP($B22,'Stock Data'!$A$1:$E$33,4,FALSE) -> 24490000 | F22: =VLOOKUP($B22,'Stock Data'!$A$1:$E$33,5,FALSE) -> 3.2887619e+09 | G22: =VLOOKUP($B22,'Stock Data'!$A$1:$J$33,10,FALSE) -> Big Growth
A23: MICROSOFT CORP | B23: MSFT | C23: =VLOOKUP($B23,'Stock Data'!$A$1:$E$33,2,FALSE) -> 0.091 | D23: =VLOOKUP($B23,'Stock Data'!$A$1:$E$33,3,FALSE) -> 421.5 | E23: =VLOOKUP($B23,'Stock Data'!$A$1:$E$33,4,FALSE) -> 7434881 | F23: =VLOOKUP($B23,'Stock Data'!$A$1:$E$33,5,FALSE) -> 3.1338023e+09 | G23: =VLOOKUP($B23,'Stock Data'!$A$1:$J$33,10,FALSE) -> Big Growth
A24: APPLE INC | B24: AAPL | C24: =VLOOKUP($B24,'Stock Data'!$A$1:$E$33,2,FALSE) -> 0.016 | D24: =VLOOKUP($B24,'Stock Data'!$A$1:$E$33,3,FALSE) -> 250.42 | E24: =VLOOKUP($B24,'Stock Data'!$A$1:$E$33,4,FALSE) -> 15115823 | F24: =VLOOKUP($B24,'Stock Data'!$A$1:$E$33,5,FALSE) -> 3.7853044e+09 | G24: =VLOOKUP($B24,'Stock Data'!$A$1:$J$33,10,FALSE) -> Big Growth
A25: AMAZON COM INC | B25: AMZN | C25: =VLOOKUP($B25,'Stock Data'!$A$1:$E$33,2,FALSE) -> 0.132 | D25: =VLOOKUP($B25,'Stock Data'!$A$1:$E$33,3,FALSE) -> 219.39 | E25: =VLOOKUP($B25,'Stock Data'!$A$1:$E$33,4,FALSE) -> 10515011 | F25: =VLOOKUP($B25,'Stock Data'!$A$1:$E$33,5,FALSE) -> 2.3068883e+09 | G25: =VLOOKUP($B25,'Stock Data'!$A$1:$J$33,10,FALSE) -> Big Growth
A26: META PLATFORMS INC | B26: META | C26: =VLOOKUP($B26,'Stock Data'!$A$1:$E$33,2,FALSE) -> 0.114 | D26: =VLOOKUP($B26,'Stock Data'!$A$1:$E$33,3,FALSE) -> 585.51001 | E26: =VLOOKUP($B26,'Stock Data'!$A$1:$E$33,4,FALSE) -> 2180001 | F26: =VLOOKUP($B26,'Stock Data'!$A$1:$E$33,5,FALSE) -> 1.2764124e+09 | G26: =VLOOKUP($B26,'Stock Data'!$A$1:$J$33,10,FALSE) -> Big Growth
A27: ALPHABET INC | B27: GOOGL | C27: =VLOOKUP($B27,'Stock Data'!$A$1:$E$33,2,FALSE) -> 0.154 | D27: =VLOOKUP($B27,'Stock Data'!$A$1:$E$33,3,FALSE) -> 189.3 | E27: =VLOOKUP($B27,'Stock Data'!$A$1:$E$33,4,FALSE) -> 5843000 | F27: =VLOOKUP($B27,'Stock Data'!$A$1:$E$33,5,FALSE) -> 1106079900 | G27: =VLOOKUP($B27,'Stock Data'!$A$1:$J$33,10,FALSE) -> Big Growth
A28: ROYAL CARIBBEAN CRUISES LTD | B28: RCL | C28: =VLOOKUP($B28,'Stock Data'!$A$1:$E$33,2,FALSE) -> 0.14 | D28: =VLOOKUP($B28,'Stock Data'!$A$1:$E$33,3,FALSE) -> 230.69 | E28: =VLOOKUP($B28,'Stock Data'!$A$1:$E$33,4,FALSE) -> 268875 | F28: =VLOOKUP($B28,'Stock Data'!$A$1:$E$33,5,FALSE) -> 62026774 | G28: =VLOOKUP($B28,'Stock Data'!$A$1:$J$33,10,FALSE) -> Small Growth
A29: VISA INC | B29: V | C29: =VLOOKUP($B29,'Stock Data'!$A$1:$E$33,2,FALSE) -> 0.08 | D29: =VLOOKUP($B29,'Stock Data'!$A$1:$E$33,3,FALSE) -> 316.04001 | E29: =VLOOKUP($B29,'Stock Data'!$A$1:$E$33,4,FALSE) -> 1729399 | F29: =VLOOKUP($B29,'Stock Data'!$A$1:$E$33,5,FALSE) -> 5.4655928e+08 | G29: =VLOOKUP($B29,'Stock Data'!$A$1:$J$33,10,FALSE) -> Big Growth
A30: LILLY ELI & CO | B30: LLY | C30: =VLOOKUP($B30,'Stock Data'!$A$1:$E$33,2,FALSE) -> 0.018 | D30: =VLOOKUP($B30,'Stock Data'!$A$1:$E$33,3,FALSE) -> 772 | E30: =VLOOKUP($B30,'Stock Data'!$A$1:$E$33,4,FALSE) -> 949316 | F30: =VLOOKUP($B30,'Stock Data'!$A$1:$E$33,5,FALSE) -> 732871952 | G30: =VLOOKUP($B30,'Stock Data'!$A$1:$J$33,10,FALSE) -> Big Growth
A31: BROADCOM INC | B31: AVGO | C31: =VLOOKUP($B31,'Stock Data'!$A$1:$E$33,2,FALSE) -> 0.091 | D31: =VLOOKUP($B31,'Stock Data'!$A$1:$E$33,3,FALSE) -> 231.84 | E31: =VLOOKUP($B31,'Stock Data'!$A$1:$E$33,4,FALSE) -> 4686000 | F31: =VLOOKUP($B31,'Stock Data'!$A$1:$E$33,5,FALSE) -> 1086402240 | G31: =VLOOKUP($B31,'Stock Data'!$A$1:$J$33,10,FALSE) -> Big Growth
A32: GENERAL ELECTRIC CO | B32: GE | C32: =VLOOKUP($B32,'Stock Data'!$A$1:$E$33,2,FALSE) -> 0.092 | D32: =VLOOKUP($B32,'Stock Data'!$A$1:$E$33,3,FALSE) -> 166.78999 | E32: =VLOOKUP($B32,'Stock Data'!$A$1:$E$33,4,FALSE) -> 1082294 | F32: =VLOOKUP($B32,'Stock Data'!$A$1:$E$33,5,FALSE) -> 1.8051581e+08 | G32: =VLOOKUP($B32,'Stock Data'!$A$1:$J$33,10,FALSE) -> Big Growth
A33: NETFLIX INC | B33: NFLX | C33: =VLOOKUP($B33,'Stock Data'!$A$1:$E$33,2,FALSE) -> 0.075 | D33: =VLOOKUP($B33,'Stock Data'!$A$1:$E$33,3,FALSE) -> 891.32001 | E33: =VLOOKUP($B33,'Stock Data'!$A$1:$E$33,4,FALSE) -> 427458 | F33: =VLOOKUP($B33,'Stock Data'!$A$1:$E$33,5,FALSE) -> 3.8100187e+08 | G33: =VLOOKUP($B33,'Stock Data'!$A$1:$J$33,10,FALSE) -> Big Growth
... A36: INTUITIVE SURGICAL INC | B36: ISRG | C36: =VLOOKUP($B36,'Stock Data'!$A$1:$E$33,2,FALSE) -> 0.089 | D36: =VLOOKUP($B36,'Stock Data'!$A$1:$E$33,3,FALSE) -> 521.96002 | E36: =VLOOKUP($B36,'Stock Data'!$A$1:$E$33,4,FALSE) -> 356179 | F36: =VLOOKUP($B36,'Stock Data'!$A$1:$E$33,5,FALSE) -> 1.859112e+08 | G36: =VLOOKUP($B36,'Stock Data'!$A$1:$J$33,10,FALSE) -> Big Growth
A39: SPFIX
A40: security_name | B40: Ticker | C40: =VLOOKUP(B40,'Stock Data'!$A$1:$E$33,2,FALSE) -> BM | D40: =VLOOKUP($B40,'Stock Data'!$A$1:$E$33,3,FALSE) -> PRC | E40: =VLOOKUP($B40,'Stock Data'!$A$1:$E$33,4,FALSE) -> SHROUT | F40: =VLOOKUP($B40,'Stock Data'!$A$1:$E$33,5,FALSE) -> Size
A41: NVIDIA CORP | B41: NVDA | C41: =VLOOKUP($B41,'Stock Data'!$A$1:$E$33,2,FALSE) -> 0.02 | D41: =VLOOKUP($B41,'Stock Data'!$A$1:$E$33,3,FALSE) -> 134.28999 | E41: =VLOOKUP($B41,'Stock Data'!$A$1:$E$33,4,FALSE) -> 24490000 | F41: =VLOOKUP($B41,'Stock Data'!$A$1:$E$33,5,FALSE) -> 3.2887619e+09 | G41: =VLOOKUP($B41,'Stock Data'!$A$1:$J$33,10,FALSE) -> Big Growth
A42: MICROSOFT CORP | B42: MSFT | C42: =VLOOKUP($B42,'Stock Data'!$A$1:$E$33,2,FALSE) -> 0.091 | D42: =VLOOKUP($B42,'Stock Data'!$A$1:$E$33,3,FALSE) -> 421.5 | E42: =VLOOKUP($B42,'Stock Data'!$A$1:$E$33,4,FALSE) -> 7434881 | F42: =VLOOKUP($B42,'Stock Data'!$A$1:$E$33,5,FALSE) -> 3.1338023e+09 | G42: =VLOOKUP($B42,'Stock Data'!$A$1:$J$33,10,FALSE) -> Big Growth
A43: APPLE INC | B43: AAPL | C43: =VLOOKUP($B43,'Stock Data'!$A$1:$E$33,2,FALSE) -> 0.016 | D43: =VLOOKUP($B43,'Stock Data'!$A$1:$E$33,3,FALSE) -> 250.42 | E43: =VLOOKUP($B43,'Stock Data'!$A$1:$E$33,4,FALSE) -> 15115823 | F43: =VLOOKUP($B43,'Stock Data'!$A$1:$E$33,5,FALSE) -> 3.7853044e+09 | G43: =VLOOKUP($B43,'Stock Data'!$A$1:$J$33,10,FALSE) -> Big Growth
A44: AMAZON COM INC | B44: AMZN | C44: =VLOOKUP($B44,'Stock Data'!$A$1:$E$33,2,FALSE) -> 0.132 | D44: =VLOOKUP($B44,'Stock Data'!$A$1:$E$33,3,FALSE) -> 219.39 | E44: =VLOOKUP($B44,'Stock Data'!$A$1:$E$33,4,FALSE) -> 10515011 | F44: =VLOOKUP($B44,'Stock Data'!$A$1:$E$33,5,FALSE) -> 2.3068883e+09 | G44: =VLOOKUP($B44,'Stock Data'!$A$1:$J$33,10,FALSE) -> Big Growth
...

Sheet Investment
A2: Amt Needed | B2: Tax | C2: Withdrawal Amt
A3: 8000 | B3: 0.22 | C3: =A3/(1-B3) -> 10256.41
A6: 100% Each | G6: 1/3 Each
B7: FGINX | C7: PGWCX | D7: SPFIX | H7: FGINX | I7: PGWCX | J7: SPFIX | K7: Total
A8: Date | B8: Remaining Inv | C8: Remaining Inv | D8: Remaining Inv | E8: Withdrawal | G8: Date | H8: Remaining Inv | I8: Remaining Inv | J8: Remaining Inv | K8: Remaining Inv | L8: Withdrawal | M8: Withdrawal/3
A9: Initial Inv | B9: 1000000 | C9: 1000000 | D9: 1000000 | E9: =C3 -> 10256.41 | G9: Initial Inv | H9: =$K$9/3 -> 333333.33 | I9: =$K$9/3 -> 333333.33 | J9: =$K$9/3 -> 333333.33 | K9: 1000000 | L9: =C3 -> 10256.41 | M9: =L9/3 -> 3418.8034
A10: ='MF Data '!A194 -> 41670 | B10: =(B9-$E$9)*(1+'MF Data '!B194) -> 938292.76 | C10: =(C9-$E$9)*(1+'MF Data '!C194) -> 981319.88 | D10: =(D9-$E$9)*(1+'MF Data '!D194) -> 953989.1 | G10: =A10 -> 41670 | H10: =(H9-($M$9))*(1+'MF Data '!B194) -> 312764.25 | I10: =(I9-($M$9))*(1+'MF Data '!C194) -> 327106.63 | J10: =(J9-($M$9))*(1+'MF Data '!D194) -> 317996.37 | K10: =SUM(H10:J10) -> 957867.25
A11: ='MF Data '!A195 -> 41698 | B11: =(B10-$E$9)*(1+'MF Data '!B195) -> 974014.05 | C11: =(C10-$E$9)*(1+'MF Data '!C195) -> 1027807.6 | D11: =(D10-$E$9)*(1+'MF Data '!D195) -> 986439.43 | G11: =A11 -> 41698 | H11: =(H10-($M$9))*(1+'MF Data '!B195) -> 324671.35 | I11: =(I10-($M$9))*(1+'MF Data '!C195) -> 342602.52 | J11: =(J10-($M$9))*(1+'MF Data '!D195) -> 328813.14 | K11: =SUM(H11:J11) -> 996087.02
A12: ='MF Data '!A196 -> 41729 | B12: =(B11-$E$9)*(1+'MF Data '!B196) -> 969631.75 | C12: =(C11-$E$9)*(1+'MF Data '!C196) -> 978511.79 | D12: =(D11-$E$9)*(1+'MF Data '!D196) -> 984552.81 | G12: =A12 -> 41729 | H12: =(H11-($M$9))*(1+'MF Data '!B196) -> 323210.58 | I12: =(I11-($M$9))*(1+'MF Data '!C196) -> 326170.6 | J12: =(J11-($M$9))*(1+'MF Data '!D196) -> 328184.27 | K12: =SUM(H12:J12) -> 977565.45
A13: ='MF Data '!A197 -> 41759 | B13: =(B12-$E$9)*(1+'MF Data '!B197) -> 962877.06 | C13: =(C12-$E$9)*(1+'MF Data '!C197) -> 956949.06 | D13: =(D12-$E$9)*(1+'MF Data '!D197) -> 981509.12 | G13: =A13 -> 41759 | H13: =(H12-($M$9))*(1+'MF Data '!B197) -> 320959.02 | I13: =(I12-($M$9))*(1+'MF Data '!C197) -> 318983.02 | J13: =(J12-($M$9))*(1+'MF Data '!D197) -> 327169.71 | K13: =SUM(H13:J13) -> 967111.74
A14: ='MF Data '!A198 -> 41789 | B14: =(B13-$E$9)*(1+'MF Data '!B198) -> 972972.43 | C14: =(C13-$E$9)*(1+'MF Data '!C198) -> 979937.66 | D14: =(D13-$E$9)*(1+'MF Data '!D198) -> 993431.26 | G14: =A14 -> 41789 | H14: =(H13-($M$9))*(1+'MF Data '!B198) -> 324324.14 | I14: =(I13-($M$9))*(1+'MF Data '!C198) -> 326645.89 | J14: =(J13-($M$9))*(1+'MF Data '!D198) -> 331143.75 | K14: =SUM(H14:J14) -> 982113.78
A15: ='MF Data '!A199 -> 41820 | B15: =(B14-$E$9)*(1+'MF Data '!B199) -> 985981.02 | C15: =(C14-$E$9)*(1+'MF Data '!C199) -> 982593.52 | D15: =(D14-$E$9)*(1+'MF Data '!D199) -> 1002772.5 | G15: =A15 -> 41820 | H15: =(H14-($M$9))*(1+'MF Data '!B199) -> 328660.34 | I15: =(I14-($M$9))*(1+'MF Data '!C199) -> 327531.17 | J15: =(J14-($M$9))*(1+'MF Data '!D199) -> 334257.49 | K15: =SUM(H15:J15) -> 990449
A16: ='MF Data '!A200 -> 41851 | B16: =(B15-$E$9)*(1+'MF Data '!B200) -> 957891.29 | C16: =(C15-$E$9)*(1+'MF Data '!C200) -> 954083.43 | D16: =(D15-$E$9)*(1+'MF Data '!D200) -> 978978.15 | G16: =A16 -> 41851 | H16: =(H15-($M$9))*(1+'MF Data '!B200) -> 319297.1 | I16: =(I15-($M$9))*(1+'MF Data '!C200) -> 318027.81 | J16: =(J15-($M$9))*(1+'MF Data '!D200) -> 326326.05 | K16: =SUM(H16:J16) -> 963650.95
A17: ='MF Data '!A201 -> 41880 | B17: =(B16-$E$9)*(1+'MF Data '!B201) -> 987539.78 | C17: =(C16-$E$9)*(1+'MF Data '!C201) -> 989874.45 | D17: =(D16-$E$9)*(1+'MF Data '!D201) -> 1007421.2 | G17: =A17 -> 41880 | H17: =(H16-($M$9))*(1+'MF Data '!B201) -> 329179.93 | I17: =(I16-($M$9))*(1+'MF Data '!C201) -> 329958.15 | J17: =(J16-($M$9))*(1+'MF Data '!D201) -> 335807.07 | K17: =SUM(H17:J17) -> 994945.14
A18: ='MF Data '!A202 -> 41912 | B18: =(B17-$E$9)*(1+'MF Data '!B202) -> 947478.19 | C18: =(C17-$E$9)*(1+'MF Data '!C202) -> 953407.38 | D18: =(D17-$E$9)*(1+'MF Data '!D202) -> 982696.93 | G18: =A18 -> 41912 | H18: =(H17-($M$9))*(1+'MF Data '!B202) -> 315826.06 | I18: =(I17-($M$9))*(1+'MF Data '!C202) -> 317802.46 | J18: =(J17-($M$9))*(1+'MF Data '!D202) -> 327565.64 | K18: =SUM(H18:J18) -> 961194.16
A19: ='MF Data '!A203 -> 41943 | B19: =(B18-$E$9)*(1+'MF Data '!B203) -> 952869.63 | C19: =(C18-$E$9)*(1+'MF Data '!C203) -> 969963.81 | D19: =(D18-$E$9)*(1+'MF Data '!D203) -> 996348.94 | G19: =A19 -> 41943 | H19: =(H18-($M$9))*(1+'MF Data '!B203) -> 317623.21 | I19: =(I18-($M$9))*(1+'MF Data '!C203) -> 323321.27 | J19: =(J18-($M$9))*(1+'MF Data '!D203) -> 332116.31 | K19: =SUM(H19:J19) -> 973060.79
A20: ='MF Data '!A204 -> 41971 | B20: =(B19-$E$9)*(1+'MF Data '!B204) -> 957277.45 | C20: =(C19-$E$9)*(1+'MF Data '!C204) -> 974283.43 | D20: =(D19-$E$9)*(1+'MF Data '!D204) -> 1012790 | G20: =A20 -> 41971 | H20: =(H19-($M$9))*(1+'MF Data '!B204) -> 319092.48 | I20: =(I19-($M$9))*(1+'MF Data '!C204) -> 324761.14 | J20: =(J19-($M$9))*(1+'MF Data '!D204) -> 337596.67 | K20: =SUM(H20:J20) -> 981450.29
A21: ='MF Data '!A205 -> 42004 | B21: =(B20-$E$9)*(1+'MF Data '!B205) -> 943334.29 | C21: =(C20-$E$9)*(1+'MF Data '!C205) -> 954995.05 | D21: =(D20-$E$9)*(1+'MF Data '!D205) -> 999740.53 | G21: =A21 -> 42004 | H21: =(H20-($M$9))*(1+'MF Data '!B205) -> 314444.76 | I21: =(I20-($M$9))*(1+'MF Data '!C205) -> 318331.68 | J21: =(J20-($M$9))*(1+'MF Data '!D205) -> 333246.84 | K21: =SUM(H21:J21) -> 966023.29
... A141: ='MF Data '!A325 -> 45657 | B141: =(B140-$E$9)*(1+'MF Data '!B325) -> 12195.681 | C141: =(C140-$E$9)*(1+'MF Data '!C325) -> 986459.38 | D141: =(D140-$E$9)*(1+'MF Data '!D325) -> 682484.12 | G141: =A141 -> 45657 | H141: =(H140-($M$9))*(1+'MF Data '!B325) -> 4065.2271 | I141: =(I140-($M$9))*(1+'MF Data '!C325) -> 328819.79 | J141: =(J140-($M$9))*(1+'MF Data '!D325) -> 227494.71 | K141: =SUM(H141:J141) -> 560379.73

Sheet Sharpe+Treynor Ratio
A1: Sharpe
A2: Fund | B2: Period | C2: Avg Excess Return | D2: SD | E2: Sharpe Ratio( Monthly | F2: Sharpe Ratio (Annually)
A3: FGINX | B3: 1998-2013 (Full) | C3: =AVERAGE('MF Data '!F2:F193) -> 0.0042549687 | D3: =_xlfn.STDEV.S('MF Data '!F2:F193) -> 0.046909273 | E3: =(C3/D3) -> 0.090706346 | F3: =E3*SQRT(12) -> 0.314216
A4: PGWCX | B4: 1998-2013 (Full) | C4: =AVERAGE('MF Data '!G2:G193) -> 0.0039318594 | D4: =_xlfn.STDEV.S('MF Data '!G2:G193) -> 0.055518417 | E4: =(C4/D4) -> 0.070820813 | F4: =E4*SQRT(12) -> 0.24533049
A5: SPFIX | B5: 1998-2013 (Full) | C5: =AVERAGE('MF Data '!H2:H193) -> 0.0039919167 | D5: =_xlfn.STDEV.S('MF Data '!H2:H193) -> 0.04575747 | E5: =(C5/D5) -> 0.087240765 | F5: =E5*SQRT(12) -> 0.30221088
A6: FGINX | B6: 1998-2006 (1st Half) | C6: =AVERAGE('MF Data '!F2:F109) -> 0.0029235093 | D6: =_xlfn.STDEV.S('MF Data '!F2:F109) -> 0.04246463 | E6: =(C6/D6) -> 0.06884575 | F6: =E6*SQRT(12) -> 0.23848867
A7: PGWCX | B7: 1998-2006 (1st Half) | C7: =AVERAGE('MF Data '!G2:G109) -> 0.0015289815 | D7: =_xlfn.STDEV.S('MF Data '!G2:G109) -> 0.059306811 | E7: =(C7/D7) -> 0.025780875 | F7: =E7*SQRT(12) -> 0.089307571
A8: SPFIX | B8: 1998-2006 (1st Half) | C8: =AVERAGE('MF Data '!H2:H109) -> 0.0029734722 | D8: =_xlfn.STDEV.S('MF Data '!H2:H109) -> 0.043646236 | E8: =(C8/D8) -> 0.068126659 | F8: =E8*SQRT(12) -> 0.23599767
A9: FGINX | B9: 2007-2013 (2nd Half) | C9: =AVERAGE('MF Data '!F110:F193) -> 0.0059668452 | D9: =_xlfn.STDEV.S('MF Data '!F110:F193) -> 0.052285919 | E9: =(C9/D9) -> 0.11411954 | F9: =E9*SQRT(12) -> 0.39532169
A10: PGWCX | B10: 2007-2013 (2nd Half) | C10: =AVERAGE('MF Data '!G110:G193) -> 0.0070212738 | D10: =_xlfn.STDEV.S('MF Data '!G110:G193) -> 0.050413004 | E10: =(C10/D10) -> 0.13927505 | F10: =E10*SQRT(12) -> 0.48246294
A11: SPFIX | B11: 2007-2013 (2nd Half) | C11: =AVERAGE('MF Data '!H110:H193) -> 0.0053013452 | D11: =_xlfn.STDEV.S('MF Data '!H110:H193) -> 0.048571782 | E11: =(C11/D11) -> 0.10914455 | F11: =E11*SQRT(12) -> 0.37808781
A13: Treynor
A14: =A2 -> Fund | B14: =B2 -> Period | C14: =C2 -> Avg Excess Return | D14: Beta | E14: Treynor Ratio (Monthly) | F14: Treynor Ratio (Annually
A15: =A3 -> FGINX | B15: =B3 -> 1998-2013 (Full) | C15: =C3 -> 0.0042549687 | D15: ='Alphas 1998-2013'!B21 -> 0.95407921 | E15: =C15/D15 -> 0.0044597647 | F15: =E15*12 -> 0.053517176
A16: =A4 -> PGWCX | B16: =B4 -> 1998-2013 (Full) | C16: =C4 -> 0.0039318594 | D16: ='Alphas 1998-2013'!B44 -> 1.0780906 | E16: =C16/D16 -> 0.0036470584 | F16: =E16*12 -> 0.043764701
A17: =A5 -> SPFIX | B17: =B5 -> 1998-2013 (Full) | C17: =C5 -> 0.0039919167 | D17: ='Alphas 1998-2013'!B67 -> 0.94495876 | E17: =C17/D17 -> 0.0042244348 | F17: =E17*12 -> 0.050693217
A18: =A6 -> FGINX | B18: =B6 -> 1998-2006 (1st Half) | C18: =C6 -> 0.0029235093 | D18: ='Alphas 1998-2006 '!B21 -> 0.88101929 | E18: =C18/D18 -> 0.0033183261 | F18: =E18*12 -> 0.039819913
A19: =A7 -> PGWCX | B19: =B7 -> 1998-2006 (1st Half) | C19: =C7 -> 0.0015289815 | D19: ='Alphas 1998-2006 '!B45 -> 1.1848486 | E19: =C19/D19 -> 0.0012904446 | F19: =E19*12 -> 0.015485335
A20: =A8 -> SPFIX | B20: =B8 -> 1998-2006 (1st Half) | C20: =C8 -> 0.0029734722 | D20: ='Alphas 1998-2006 '!B69 -> 0.92418962 | E20: =C20/D20 -> 0.0032173833 | F20: =E20*12 -> 0.038608599
A21: =A9 -> FGINX | B21: =B9 -> 2007-2013 (2nd Half) | C21: =C9 -> 0.0059668452 | D21: ='Alphas 2007-2013'!B21 -> 1.033834 | E21: =C21/D21 -> 0.0057715702 | F21: =E21*12 -> 0.069258842
A22: =A10 -> PGWCX | B22: =B10 -> 2007-2013 (2nd Half) | C22: =C10 -> 0.0070212738 | D22: ='Alphas 2007-2013'!B45 -> 0.95954028 | E22: =C22/D22 -> 0.0073173309 | F22: =E22*12 -> 0.087807971
A23: =A11 -> SPFIX | B23: =B11 -> 2007-2013 (2nd Half) | C23: =C11 -> 0.0053013452 | D23: ='Alphas 2007-2013'!B69 -> 0.96784445 | E23: =C23/D23 -> 0.0054774765 | F23: =E23*12 -> 0.065729718

Sheet Alphas 1998-2013
A1: Alphas 1998-2013
A3: FGINX
A4: 1-Factor | K4: 3-Factor | U4: 4-Factor
A6: Regression Statistics | K6: Regression Statistics | U6: Regression Statistics
A7: Multiple R | B7: 0.97215414 | K7: Multiple R | L7: 0.97490033 | U7: Multiple R | V7: 0.97619753
A8: R Square | B8: 0.94508368 | K8: R Square | L8: 0.95043066 | U8: R Square | V8: 0.95296161
A9: Adjusted R Square | B9: 0.94479465 | K9: Adjusted R Square | L9: 0.94963966 | U9: Adjusted R Square | V9: 0.95195545
A10: Standard Error | B10: 0.011021718 | K10: Standard Error | L10: 0.010526961 | U10: Standard Error | V10: 0.010282075
A11: Observations | B11: 192 | K11: Observations | L11: 192 | U11: Observations | V11: 192
A13: ANOVA | K13: ANOVA | U13: ANOVA
B14: df | C14: SS | D14: MS | E14: F | F14: Significance F | L14: df | M14: SS | N14: MS | O14: F | P14: Significance F | V14: df | W14: SS | X14: MS | Y14: F | Z14: Significance F
A15: Regression | B15: 1 | C15: 0.39721079 | D15: 0.39721079 | E15: 3269.8095 | F15: 1.1111174e-121 | K15: Regression | L15: 3 | M15: 0.39945808 | N15: 0.13315269 | O15: 1201.5557 | P15: 2.3980537e-122 | U15: Regression | V15: 4 | W15: 0.40052182 | X15: 0.10013045 | Y15: 947.11915 | Z15: 6.7458046e-123
A16: Residual | B16: 190 | C16: 0.023080871 | D16: 0.00012147827 | K16: Residual | L16: 188 | M16: 0.02083358 | N16: 0.00011081691 | U16: Residual | V16: 187 | W16: 0.019769841 | X16: 0.00010572107
A17: Total | B17: 191 | C17: 0.42029166 | K17: Total | L17: 191 | M17: 0.42029166 | U17: Total | V17: 191 | W17: 0.42029166
B19: Coefficients | C19: Standard Error | D19: t Stat | E19: P-value | F19: Lower 95% | G19: Upper 95% | H19: Lower 95.0% | I19: Upper 95.0% | L19: Coefficients | M19: Standard Error | N19: t Stat | O19: P-value | P19: Lower 95% | Q19: Upper 95% | R19: Lower 95.0% | S19: Upper 95.0% | V19: Coefficients | W19: Standard Error | X19: t Stat | Y19: P-value | Z19: Lower 95% | AA19: Upper 95% | AB19: Lower 95.0% | AC19: Upper 95.0%
A20: Intercept | B20: -0.0001124282 | C20: 0.00079908242 | D20: -0.14069663 | E20: 0.88825866 | F20: -0.0016886408 | G20: 0.0014637844 | H20: -0.0016886408 | I20: 0.0014637844 | K20: Intercept | L20: -0.00048362611 | M20: 0.00076852617 | N20: -0.62929036 | O20: 0.52992292 | P20: -0.001999669 | Q20: 0.0010324168 | R20: -0.001999669 | S20: 0.0010324168 | U20: Intercept | V20: -0.00075589699 | W20: 0.00075553974 | X20: -1.0004728 | Y20: 0.31837457 | Z20: -0.0022463737 | AA20: 0.0007345797 | AB20: -0.0022463737 | AC20: 0.0007345797
A21: Rm-Rf | B21: 0.95407921 | C21: 0.016684885 | D21: 57.182248 | E21: 1.1111174e-121 | F21: 0.9211678 | G21: 0.98699061 | H21: 0.9211678 | I21: 0.98699061 | K21: Rm-Rf | L21: 0.9567221 | M21: 0.016543287 | N21: 57.831439 | O21: 1.0651975e-121 | P21: 0.92408777 | Q21: 0.98935642 | R21: 0.92408777 | S21: 0.98935642 | U21: Rm-Rf | V21: 0.97732592 | W21: 0.017415124 | X21: 56.119376 | Y21: 5.8709016e-119 | Z21: 0.94297056 | AA21: 1.0116813 | AB21: 0.94297056 | AC21: 1.0116813
K22: smb | L22: 0.039949549 | M22: 0.02344224 | N22: 1.7041694 | O22: 0.090001577 | P22: -0.0062940837 | Q22: 0.086193181 | R22: -0.0062940837 | S22: 0.086193181 | U22: smb | V22: 0.02841249 | W22: 0.023183985 | X22: 1.2255223 | Y22: 0.22191974 | Z22: -0.017323276 | AA22: 0.074148256 | AB22: -0.017323276 | AC22: 0.074148256
K23: hml | L23: 0.10924891 | M23: 0.024373369 | N23: 4.4823064 | O23: 1.2813457e-05 | P23: 0.061168474 | Q23: 0.15732935 | R23: 0.061168474 | S23: 0.15732935 | U23: hml | V23: 0.12406316 | W23: 0.024260156 | X23: 5.113865 | Y23: 7.7752884e-07 | Z23: 0.076204398 | AA23: 0.17192192 | AB23: 0.076204398 | AC23: 0.17192192
U24: momentum | V24: 0.044565455 | W24: 0.014049524 | X24: 3.1720259 | Y24: 0.0017696463 | Z24: 0.016849522 | AA24: 0.072281388 | AB24: 0.016849522 | AC24: 0.072281388
A26: PGWCX
A27: 1-Factor | K27: 3-Factor | U27: 4-Factor
A29: Regression Statistics | K29: Regression Statistics | U29: Regression Statistics
A30: Multiple R | B30: 0.92817013 | K30: Multiple R | L30: 0.9500373 | U30: Multiple R | V30: 0.96439259
A31: R Square | B31: 0.8614998 | K31: R Square | L31: 0.90257086 | U31: R Square | V31: 0.93005307
A32: Adjusted R Square | B32: 0.86077085 | K32: Adjusted R Square | L32: 0.90101614 | U32: Adjusted R Square | V32: 0.92855688
A33: Standard Error | B33: 0.020715821 | K33: Standard Error | L33: 0.017467038 | U33: Standard Error | V33: 0.014839432
A34: Observations | B34: 192 | K34: Observations | L34: 192 | U34: Observations | V34: 192
A36: ANOVA | K36: ANOVA | U36: ANOVA
B37: df | C37: SS | D37: MS | E37: F | F37: Significance F | L37: df | M37: SS | N37: MS | O37: F | P37: Significance F | V37: df | W37: SS | X37: MS | Y37: F | Z37: Significance F
A38: Regression | B38: 1 | C38: 0.50718067 | D38: 0.50718067 | E38: 1181.8392 | F38: 1.7052559e-83 | K38: Regression | L38: 3 | M38: 0.53135995 | N38: 0.17711998 | O38: 580.53586 | P38: 9.025782e-95 | U38: Regression | V38: 4 | W38: 0.54753923 | X38: 0.13688481 | Y38: 621.61388 | Z38: 8.514382e-107
A39: Residual | B39: 190 | C39: 0.081537598 | D39: 0.00042914525 | K39: Residual | L39: 188 | M39: 0.057358312 | N39: 0.0003050974 | U39: Residual | V39: 187 | W39: 0.041179034 | X39: 0.00022020874
A40: Total | B40: 191 | C40: 0.58871826 | K40: Total | L40: 191 | M40: 0.58871826 | U40: Total | V40: 191 | W40: 0.58871826
B42: Coefficients | C42: Standard Error | D42: t Stat | E42: P-value | F42: Lower 95% | G42: Upper 95% | H42: Lower 95.0% | I42: Upper 95.0% | L42: Coefficients | M42: Standard Error | N42: t Stat | O42: P-value | P42: Lower 95% | Q42: Upper 95% | R42: Lower 95.0% | S42: Upper 95.0% | V42: Coefficients | W42: Standard Error | X42: t Stat | Y42: P-value | Z42: Lower 95% | AA42: Upper 95% | AB42: Lower 95.0% | AC42: Upper 95.0%
A43: Intercept | B43: -0.0010032126 | C43: 0.0015019118 | D43: -0.66795707 | E43: 0.50497156 | F43: -0.0039657761 | G43: 0.0019593508 | H43: -0.0039657761 | I43: 0.0019593508 | K43: Intercept | L43: -6.0577963e-05 | M43: 0.00127519 | N43: -0.047505049 | O43: 0.96216113 | P43: -0.0025760977 | Q43: 0.0024549417 | R43: -0.0025760977 | S43: 0.0024549417 | U43: Intercept | V43: -0.0011224282 | W43: 0.00109042 | X43: -1.029354 | Y43: 0.3046429 | Z43: -0.0032735335 | AA43: 0.0010286772 | AB43: -0.0032735335 | AC43: 0.0010286772
A44: Rm-Rf | B44: 1.0780906 | C44: 0.031360001 | D44: 34.377888 | E44: 1.7052559e-83 | F44: 1.0162321 | G44: 1.1399491 | H44: 1.0162321 | I44: 1.1399491 | K44: Rm-Rf | L44: 1.0466963 | M44: 0.027449728 | N44: 38.131393 | O44: 2.07051e-90 | P44: 0.99254729 | Q44: 1.1008454 | R44: 0.99254729 | S44: 1.1008454 | U44: Rm-Rf | V44: 1.1270508 | W44: 0.025134085 | X44: 44.841528 | Y44: 5.3274751e-102 | Z44: 1.077468 | AA44: 1.1766336 | AB44: 1.077468 | AC44: 1.1766336
K45: smb | L45: -0.0074978774 | M45: 0.038896931 | N45: -0.1927627 | O45: 0.8473529 | P45: -0.084228403 | Q45: 0.069232648 | R45: -0.084228403 | S45: 0.069232648 | U45: smb | V45: -0.052492143 | W45: 0.033459895 | X45: -1.5688078 | Y45: 0.11838329 | Z45: -0.11849952 | AA45: 0.01351523 | AB45: -0.11849952 | AC45: 0.01351523
K46: hml | L46: -0.34698771 | M46: 0.040441923 | N46: -8.5799013 | O46: 3.5040682e-15 | P46: -0.42676598 | Q46: -0.26720944 | R46: -0.42676598 | S46: -0.26720944 | U46: hml | V46: -0.28921247 | W46: 0.03501306 | X46: -8.2601311 | Y46: 2.599814e-14 | Z46: -0.35828382 | AA46: -0.22014112 | AB46: -0.35828382 | AC46: -0.22014112
U47: momentum | V47: 0.17380426 | W47: 0.020276739 | X47: 8.571608 | Y47: 3.7848788e-15 | Z47: 0.13380371 | AA47: 0.21380481 | AB47: 0.13380371 | AC47: 0.21380481
A49: SPFIX
...

Sheet Alphas 1998-2006 
A1: Alphas 1998-2006
A3: FGINX
A4: 1-Factor | K4: 3-Factor | U4: 4-Factor
A6: Regression Statistics | K6: Regression Statistics | U6: Regression Statistics
A7: Multiple R | B7: 0.95762682 | K7: Multiple R | L7: 0.96145061 | U7: Multiple R | V7: 0.96638827
A8: R Square | B8: 0.91704913 | K8: R Square | L8: 0.92438728 | U8: R Square | V8: 0.93390629
A9: Adjusted R Square | B9: 0.91626658 | K9: Adjusted R Square | L9: 0.92220614 | U9: Adjusted R Square | V9: 0.93133954
A10: Standard Error | B10: 0.012287875 | K10: Standard Error | L10: 0.011844043 | U10: Standard Error | V10: 0.011127067
A11: Observations | B11: 108 | K11: Observations | L11: 108 | U11: Observations | V11: 108
A13: ANOVA | K13: ANOVA | U13: ANOVA
B14: df | C14: SS | D14: MS | E14: F | F14: Significance F | L14: df | M14: SS | N14: MS | O14: F | P14: Significance F | V14: df | W14: SS | X14: MS | Y14: F | Z14: Significance F
A15: Regression | B15: 1 | C15: 0.17694205 | D15: 0.17694205 | E15: 1171.8648 | F15: 4.0198833e-59 | K15: Regression | L15: 3 | M15: 0.17835793 | N15: 0.059452643 | O15: 423.80999 | P15: 3.834981e-58 | U15: Regression | V15: 4 | W15: 0.18019459 | X15: 0.045048649 | Y15: 363.84833 | Z15: 8.4975759e-60
A16: Residual | B16: 106 | C16: 0.016005137 | D16: 0.00015099186 | K16: Residual | L16: 104 | M16: 0.014589262 | N16: 0.00014028136 | U16: Residual | V16: 103 | W16: 0.012752596 | X16: 0.00012381161
A17: Total | B17: 107 | C17: 0.19294719 | K17: Total | L17: 107 | M17: 0.19294719 | U17: Total | V17: 107 | W17: 0.19294719
B19: Coefficients | C19: Standard Error | D19: t Stat | E19: P-value | F19: Lower 95% | G19: Upper 95% | H19: Lower 95.0% | I19: Upper 95.0% | L19: Coefficients | M19: Standard Error | N19: t Stat | O19: P-value | P19: Lower 95% | Q19: Upper 95% | R19: Lower 95.0% | S19: Upper 95.0% | V19: Coefficients | W19: Standard Error | X19: t Stat | Y19: P-value | Z19: Lower 95% | AA19: Upper 95% | AB19: Lower 95.0% | AC19: Upper 95.0%
A20: Intercept | B20: -7.2772083e-05 | C20: 0.0011856365 | D20: -0.061378074 | E20: 0.95117369 | F20: -0.0024234117 | G20: 0.0022778675 | H20: -0.0024234117 | I20: 0.0022778675 | K20: Intercept | L20: -0.0010731296 | M20: 0.001187363 | N20: -0.90379232 | O20: 0.36819428 | P20: -0.003427715 | Q20: 0.0012814558 | R20: -0.003427715 | S20: 0.0012814558 | U20: Intercept | V20: -0.0017551392 | W20: 0.0011294534 | X20: -1.5539723 | Y20: 0.12325842 | Z20: -0.0039951436 | AA20: 0.00048486514 | AB20: -0.0039951436 | AC20: 0.00048486514
A21: Rm-Rf | B21: 0.88101929 | C21: 0.025736332 | D21: 34.232512 | E21: 4.0198833e-59 | F21: 0.82999451 | G21: 0.93204407 | H21: 0.82999451 | I21: 0.93204407 | K21: Rm-Rf | L21: 0.92148046 | M21: 0.02853415 | N21: 32.293951 | O21: 5.0469839e-56 | P21: 0.86489617 | Q21: 0.97806475 | R21: 0.86489617 | S21: 0.97806475 | U21: Rm-Rf | V21: 0.95800022 | W21: 0.028434352 | X21: 33.691649 | Y21: 1.9799709e-57 | Z21: 0.90160739 | AA21: 1.0143931 | AB21: 0.90160739 | AC21: 1.0143931
K22: smb | L22: 0.04288886 | M22: 0.030229797 | N22: 1.4187611 | O22: 0.15895862 | P22: -0.017057962 | Q22: 0.10283568 | R22: -0.017057962 | S22: 0.10283568 | U22: smb | V22: 0.016250756 | W22: 0.029229868 | X22: 0.55596407 | Y22: 0.57944114 | Z22: -0.041719793 | AA22: 0.074221306 | AB22: -0.041719793 | AC22: 0.074221306
K23: hml | L23: 0.12828514 | M23: 0.040382637 | N23: 3.17674 | O23: 0.0019609331 | P23: 0.048204854 | Q23: 0.20836542 | R23: 0.048204854 | S23: 0.20836542 | U23: hml | V23: 0.14318814 | W23: 0.038134893 | X23: 3.7547801 | Y23: 0.0002875047 | Z23: 0.06755657 | AA23: 0.2188197 | AB23: 0.06755657 | AC23: 0.2188197
U24: momentum | V24: 0.075273827 | W24: 0.019543827 | X24: 3.8515397 | Y24: 0.00020416193 | Z24: 0.036513255 | AA24: 0.1140344 | AB24: 0.036513255 | AC24: 0.1140344
A27: PGWCX
A28: 1-Factor | K28: 3-Factor | U28: 4-Factor
A30: Regression Statistics | K30: Regression Statistics | U30: Regression Statistics
A31: Multiple R | B31: 0.92213927 | K31: Multiple R | L31: 0.93719739 | U31: Multiple R | V31: 0.96951102
A32: R Square | B32: 0.85034083 | K32: R Square | L32: 0.87833895 | U32: R Square | V32: 0.93995162
A33: Adjusted R Square | B33: 0.84892895 | K33: Adjusted R Square | L33: 0.8748295 | U33: Adjusted R Square | V33: 0.93761964
A34: Standard Error | B34: 0.023051288 | K34: Standard Error | L34: 0.02098242 | U34: Standard Error | V34: 0.014812505
A35: Observations | B35: 108 | K35: Observations | L35: 108 | U35: Observations | V35: 108
A37: ANOVA | K37: ANOVA | U37: ANOVA
B38: df | C38: SS | D38: MS | E38: F | F38: Significance F | L38: df | M38: SS | N38: MS | O38: F | P38: Significance F | V38: df | W38: SS | X38: MS | Y38: F | Z38: Significance F
